2023-07-31 12:52:20,259 (99592/MainThread) litecli.main ERROR - sql: 'database ', error: OperationalError('Not connected to database.')
2023-07-31 12:52:20,261 (99592/MainThread) litecli.main ERROR - traceback: 'Traceback (most recent call last):\n  File "/opt/homebrew/Cellar/litecli/1.9.0_2/libexec/lib/python3.11/site-packages/litecli/main.py", line 447, in one_iteration\n    for title, cur, headers, status in res:\n  File "/opt/homebrew/Cellar/litecli/1.9.0_2/libexec/lib/python3.11/site-packages/litecli/sqlexecute.py", line 122, in run\n    raise OperationalError("Not connected to database.")\nsqlite3.OperationalError: Not connected to database.\n'
2023-07-31 12:52:27,410 (99592/MainThread) litecli.main ERROR - sql: 'database kb.db', error: OperationalError('Not connected to database.')
2023-07-31 12:52:27,410 (99592/MainThread) litecli.main ERROR - traceback: 'Traceback (most recent call last):\n  File "/opt/homebrew/Cellar/litecli/1.9.0_2/libexec/lib/python3.11/site-packages/litecli/main.py", line 447, in one_iteration\n    for title, cur, headers, status in res:\n  File "/opt/homebrew/Cellar/litecli/1.9.0_2/libexec/lib/python3.11/site-packages/litecli/sqlexecute.py", line 122, in run\n    raise OperationalError("Not connected to database.")\nsqlite3.OperationalError: Not connected to database.\n'
2023-07-31 12:52:43,849 (99610/MainThread) litecli.main ERROR - sql: 'table', error: OperationalError('near "table": syntax error')
2023-07-31 12:52:43,852 (99610/MainThread) litecli.main ERROR - traceback: 'Traceback (most recent call last):\n  File "/opt/homebrew/Cellar/litecli/1.9.0_2/libexec/lib/python3.11/site-packages/litecli/sqlexecute.py", line 129, in run\n    for result in special.execute(cur, sql):\n                  ^^^^^^^^^^^^^^^^^^^^^^^^^\n  File "/opt/homebrew/Cellar/litecli/1.9.0_2/libexec/lib/python3.11/site-packages/litecli/packages/special/main.py", line 109, in execute\n    raise CommandNotFound\nlitecli.packages.special.main.CommandNotFound\n\nDuring handling of the above exception, another exception occurred:\n\nTraceback (most recent call last):\n  File "/opt/homebrew/Cellar/litecli/1.9.0_2/libexec/lib/python3.11/site-packages/litecli/main.py", line 447, in one_iteration\n    for title, cur, headers, status in res:\n  File "/opt/homebrew/Cellar/litecli/1.9.0_2/libexec/lib/python3.11/site-packages/litecli/sqlexecute.py", line 133, in run\n    cur.execute(sql)\nsqlite3.OperationalError: near "table": syntax error\n'
2023-07-31 16:16:26,307 (6419/MainThread) litecli.main ERROR - sql: 'database', error: OperationalError('Not connected to database.')
2023-07-31 16:16:26,310 (6419/MainThread) litecli.main ERROR - traceback: 'Traceback (most recent call last):\n  File "/opt/homebrew/Cellar/litecli/1.9.0_2/libexec/lib/python3.11/site-packages/litecli/main.py", line 447, in one_iteration\n    for title, cur, headers, status in res:\n  File "/opt/homebrew/Cellar/litecli/1.9.0_2/libexec/lib/python3.11/site-packages/litecli/sqlexecute.py", line 122, in run\n    raise OperationalError("Not connected to database.")\nsqlite3.OperationalError: Not connected to database.\n'
2023-07-31 16:17:03,570 (6474/MainThread) litecli.main ERROR - sql: 'table', error: OperationalError('near "table": syntax error')
2023-07-31 16:17:03,576 (6474/MainThread) litecli.main ERROR - traceback: 'Traceback (most recent call last):\n  File "/opt/homebrew/Cellar/litecli/1.9.0_2/libexec/lib/python3.11/site-packages/litecli/sqlexecute.py", line 129, in run\n    for result in special.execute(cur, sql):\n                  ^^^^^^^^^^^^^^^^^^^^^^^^^\n  File "/opt/homebrew/Cellar/litecli/1.9.0_2/libexec/lib/python3.11/site-packages/litecli/packages/special/main.py", line 109, in execute\n    raise CommandNotFound\nlitecli.packages.special.main.CommandNotFound\n\nDuring handling of the above exception, another exception occurred:\n\nTraceback (most recent call last):\n  File "/opt/homebrew/Cellar/litecli/1.9.0_2/libexec/lib/python3.11/site-packages/litecli/main.py", line 447, in one_iteration\n    for title, cur, headers, status in res:\n  File "/opt/homebrew/Cellar/litecli/1.9.0_2/libexec/lib/python3.11/site-packages/litecli/sqlexecute.py", line 133, in run\n    cur.execute(sql)\nsqlite3.OperationalError: near "table": syntax error\n'
2023-07-31 16:17:09,790 (6474/MainThread) litecli.main ERROR - sql: 'select * from urls', error: OperationalError('no such table: urls')
2023-07-31 16:17:09,791 (6474/MainThread) litecli.main ERROR - traceback: 'Traceback (most recent call last):\n  File "/opt/homebrew/Cellar/litecli/1.9.0_2/libexec/lib/python3.11/site-packages/litecli/sqlexecute.py", line 129, in run\n    for result in special.execute(cur, sql):\n                  ^^^^^^^^^^^^^^^^^^^^^^^^^\n  File "/opt/homebrew/Cellar/litecli/1.9.0_2/libexec/lib/python3.11/site-packages/litecli/packages/special/main.py", line 109, in execute\n    raise CommandNotFound\nlitecli.packages.special.main.CommandNotFound\n\nDuring handling of the above exception, another exception occurred:\n\nTraceback (most recent call last):\n  File "/opt/homebrew/Cellar/litecli/1.9.0_2/libexec/lib/python3.11/site-packages/litecli/main.py", line 447, in one_iteration\n    for title, cur, headers, status in res:\n  File "/opt/homebrew/Cellar/litecli/1.9.0_2/libexec/lib/python3.11/site-packages/litecli/sqlexecute.py", line 133, in run\n    cur.execute(sql)\nsqlite3.OperationalError: no such table: urls\n'
2023-07-31 16:17:12,503 (6474/MainThread) litecli.main ERROR - sql: 'select * from ', error: OperationalError('incomplete input')
2023-07-31 16:17:12,504 (6474/MainThread) litecli.main ERROR - traceback: 'Traceback (most recent call last):\n  File "/opt/homebrew/Cellar/litecli/1.9.0_2/libexec/lib/python3.11/site-packages/litecli/sqlexecute.py", line 129, in run\n    for result in special.execute(cur, sql):\n                  ^^^^^^^^^^^^^^^^^^^^^^^^^\n  File "/opt/homebrew/Cellar/litecli/1.9.0_2/libexec/lib/python3.11/site-packages/litecli/packages/special/main.py", line 109, in execute\n    raise CommandNotFound\nlitecli.packages.special.main.CommandNotFound\n\nDuring handling of the above exception, another exception occurred:\n\nTraceback (most recent call last):\n  File "/opt/homebrew/Cellar/litecli/1.9.0_2/libexec/lib/python3.11/site-packages/litecli/main.py", line 447, in one_iteration\n    for title, cur, headers, status in res:\n  File "/opt/homebrew/Cellar/litecli/1.9.0_2/libexec/lib/python3.11/site-packages/litecli/sqlexecute.py", line 133, in run\n    cur.execute(sql)\nsqlite3.OperationalError: incomplete input\n'
2023-07-31 16:17:19,950 (6474/MainThread) litecli.main ERROR - sql: 'table', error: OperationalError('near "table": syntax error')
2023-07-31 16:17:19,951 (6474/MainThread) litecli.main ERROR - traceback: 'Traceback (most recent call last):\n  File "/opt/homebrew/Cellar/litecli/1.9.0_2/libexec/lib/python3.11/site-packages/litecli/sqlexecute.py", line 129, in run\n    for result in special.execute(cur, sql):\n                  ^^^^^^^^^^^^^^^^^^^^^^^^^\n  File "/opt/homebrew/Cellar/litecli/1.9.0_2/libexec/lib/python3.11/site-packages/litecli/packages/special/main.py", line 109, in execute\n    raise CommandNotFound\nlitecli.packages.special.main.CommandNotFound\n\nDuring handling of the above exception, another exception occurred:\n\nTraceback (most recent call last):\n  File "/opt/homebrew/Cellar/litecli/1.9.0_2/libexec/lib/python3.11/site-packages/litecli/main.py", line 447, in one_iteration\n    for title, cur, headers, status in res:\n  File "/opt/homebrew/Cellar/litecli/1.9.0_2/libexec/lib/python3.11/site-packages/litecli/sqlexecute.py", line 133, in run\n    cur.execute(sql)\nsqlite3.OperationalError: near "table": syntax error\n'
2023-07-31 16:17:21,891 (6474/MainThread) litecli.main ERROR - sql: 'view', error: OperationalError('near "view": syntax error')
2023-07-31 16:17:21,892 (6474/MainThread) litecli.main ERROR - traceback: 'Traceback (most recent call last):\n  File "/opt/homebrew/Cellar/litecli/1.9.0_2/libexec/lib/python3.11/site-packages/litecli/sqlexecute.py", line 129, in run\n    for result in special.execute(cur, sql):\n                  ^^^^^^^^^^^^^^^^^^^^^^^^^\n  File "/opt/homebrew/Cellar/litecli/1.9.0_2/libexec/lib/python3.11/site-packages/litecli/packages/special/main.py", line 109, in execute\n    raise CommandNotFound\nlitecli.packages.special.main.CommandNotFound\n\nDuring handling of the above exception, another exception occurred:\n\nTraceback (most recent call last):\n  File "/opt/homebrew/Cellar/litecli/1.9.0_2/libexec/lib/python3.11/site-packages/litecli/main.py", line 447, in one_iteration\n    for title, cur, headers, status in res:\n  File "/opt/homebrew/Cellar/litecli/1.9.0_2/libexec/lib/python3.11/site-packages/litecli/sqlexecute.py", line 133, in run\n    cur.execute(sql)\nsqlite3.OperationalError: near "view": syntax error\n'
2023-07-31 16:17:27,829 (6474/MainThread) litecli.main ERROR - sql: 'all', error: OperationalError('near "all": syntax error')
2023-07-31 16:17:27,830 (6474/MainThread) litecli.main ERROR - traceback: 'Traceback (most recent call last):\n  File "/opt/homebrew/Cellar/litecli/1.9.0_2/libexec/lib/python3.11/site-packages/litecli/sqlexecute.py", line 129, in run\n    for result in special.execute(cur, sql):\n                  ^^^^^^^^^^^^^^^^^^^^^^^^^\n  File "/opt/homebrew/Cellar/litecli/1.9.0_2/libexec/lib/python3.11/site-packages/litecli/packages/special/main.py", line 109, in execute\n    raise CommandNotFound\nlitecli.packages.special.main.CommandNotFound\n\nDuring handling of the above exception, another exception occurred:\n\nTraceback (most recent call last):\n  File "/opt/homebrew/Cellar/litecli/1.9.0_2/libexec/lib/python3.11/site-packages/litecli/main.py", line 447, in one_iteration\n    for title, cur, headers, status in res:\n  File "/opt/homebrew/Cellar/litecli/1.9.0_2/libexec/lib/python3.11/site-packages/litecli/sqlexecute.py", line 133, in run\n    cur.execute(sql)\nsqlite3.OperationalError: near "all": syntax error\n'
2023-08-01 08:09:43,282 (11119/MainThread) litecli.main ERROR - sql: ':q', error: OperationalError('Not connected to database.')
2023-08-01 08:09:43,284 (11119/MainThread) litecli.main ERROR - traceback: 'Traceback (most recent call last):\n  File "/opt/homebrew/Cellar/litecli/1.9.0_2/libexec/lib/python3.11/site-packages/litecli/main.py", line 447, in one_iteration\n    for title, cur, headers, status in res:\n  File "/opt/homebrew/Cellar/litecli/1.9.0_2/libexec/lib/python3.11/site-packages/litecli/sqlexecute.py", line 122, in run\n    raise OperationalError("Not connected to database.")\nsqlite3.OperationalError: Not connected to database.\n'
2023-08-01 08:42:38,344 (12623/MainThread) litecli.main ERROR - sql: "select * from 'urls'", error: OperationalError('no such table: urls')
2023-08-01 08:42:38,347 (12623/MainThread) litecli.main ERROR - traceback: 'Traceback (most recent call last):\n  File "/opt/homebrew/Cellar/litecli/1.9.0_2/libexec/lib/python3.11/site-packages/litecli/sqlexecute.py", line 129, in run\n    for result in special.execute(cur, sql):\n                  ^^^^^^^^^^^^^^^^^^^^^^^^^\n  File "/opt/homebrew/Cellar/litecli/1.9.0_2/libexec/lib/python3.11/site-packages/litecli/packages/special/main.py", line 109, in execute\n    raise CommandNotFound\nlitecli.packages.special.main.CommandNotFound\n\nDuring handling of the above exception, another exception occurred:\n\nTraceback (most recent call last):\n  File "/opt/homebrew/Cellar/litecli/1.9.0_2/libexec/lib/python3.11/site-packages/litecli/main.py", line 447, in one_iteration\n    for title, cur, headers, status in res:\n  File "/opt/homebrew/Cellar/litecli/1.9.0_2/libexec/lib/python3.11/site-packages/litecli/sqlexecute.py", line 133, in run\n    cur.execute(sql)\nsqlite3.OperationalError: no such table: urls\n'
2023-08-01 08:42:40,853 (12623/MainThread) litecli.main ERROR - sql: 'select * from urls', error: OperationalError('no such table: urls')
2023-08-01 08:42:40,854 (12623/MainThread) litecli.main ERROR - traceback: 'Traceback (most recent call last):\n  File "/opt/homebrew/Cellar/litecli/1.9.0_2/libexec/lib/python3.11/site-packages/litecli/sqlexecute.py", line 129, in run\n    for result in special.execute(cur, sql):\n                  ^^^^^^^^^^^^^^^^^^^^^^^^^\n  File "/opt/homebrew/Cellar/litecli/1.9.0_2/libexec/lib/python3.11/site-packages/litecli/packages/special/main.py", line 109, in execute\n    raise CommandNotFound\nlitecli.packages.special.main.CommandNotFound\n\nDuring handling of the above exception, another exception occurred:\n\nTraceback (most recent call last):\n  File "/opt/homebrew/Cellar/litecli/1.9.0_2/libexec/lib/python3.11/site-packages/litecli/main.py", line 447, in one_iteration\n    for title, cur, headers, status in res:\n  File "/opt/homebrew/Cellar/litecli/1.9.0_2/libexec/lib/python3.11/site-packages/litecli/sqlexecute.py", line 133, in run\n    cur.execute(sql)\nsqlite3.OperationalError: no such table: urls\n'
2023-08-01 12:24:17,389 (17540/MainThread) litecli.main ERROR - sql: "select * from 'urls'", error: OperationalError('no such table: urls')
2023-08-01 12:24:17,392 (17540/MainThread) litecli.main ERROR - traceback: 'Traceback (most recent call last):\n  File "/opt/homebrew/Cellar/litecli/1.9.0_2/libexec/lib/python3.11/site-packages/litecli/sqlexecute.py", line 129, in run\n    for result in special.execute(cur, sql):\n                  ^^^^^^^^^^^^^^^^^^^^^^^^^\n  File "/opt/homebrew/Cellar/litecli/1.9.0_2/libexec/lib/python3.11/site-packages/litecli/packages/special/main.py", line 109, in execute\n    raise CommandNotFound\nlitecli.packages.special.main.CommandNotFound\n\nDuring handling of the above exception, another exception occurred:\n\nTraceback (most recent call last):\n  File "/opt/homebrew/Cellar/litecli/1.9.0_2/libexec/lib/python3.11/site-packages/litecli/main.py", line 447, in one_iteration\n    for title, cur, headers, status in res:\n  File "/opt/homebrew/Cellar/litecli/1.9.0_2/libexec/lib/python3.11/site-packages/litecli/sqlexecute.py", line 133, in run\n    cur.execute(sql)\nsqlite3.OperationalError: no such table: urls\n'
2023-08-01 12:24:46,271 (17540/MainThread) litecli.main ERROR - sql: "select * from 'urls'", error: OperationalError('no such table: urls')
2023-08-01 12:24:46,273 (17540/MainThread) litecli.main ERROR - traceback: 'Traceback (most recent call last):\n  File "/opt/homebrew/Cellar/litecli/1.9.0_2/libexec/lib/python3.11/site-packages/litecli/sqlexecute.py", line 129, in run\n    for result in special.execute(cur, sql):\n                  ^^^^^^^^^^^^^^^^^^^^^^^^^\n  File "/opt/homebrew/Cellar/litecli/1.9.0_2/libexec/lib/python3.11/site-packages/litecli/packages/special/main.py", line 109, in execute\n    raise CommandNotFound\nlitecli.packages.special.main.CommandNotFound\n\nDuring handling of the above exception, another exception occurred:\n\nTraceback (most recent call last):\n  File "/opt/homebrew/Cellar/litecli/1.9.0_2/libexec/lib/python3.11/site-packages/litecli/main.py", line 447, in one_iteration\n    for title, cur, headers, status in res:\n  File "/opt/homebrew/Cellar/litecli/1.9.0_2/libexec/lib/python3.11/site-packages/litecli/sqlexecute.py", line 133, in run\n    cur.execute(sql)\nsqlite3.OperationalError: no such table: urls\n'
2023-08-01 12:28:37,946 (17540/MainThread) litecli.main ERROR - sql: "select * from 'urls'", error: OperationalError('no such table: urls')
2023-08-01 12:28:37,950 (17540/MainThread) litecli.main ERROR - traceback: 'Traceback (most recent call last):\n  File "/opt/homebrew/Cellar/litecli/1.9.0_2/libexec/lib/python3.11/site-packages/litecli/sqlexecute.py", line 129, in run\n    for result in special.execute(cur, sql):\n                  ^^^^^^^^^^^^^^^^^^^^^^^^^\n  File "/opt/homebrew/Cellar/litecli/1.9.0_2/libexec/lib/python3.11/site-packages/litecli/packages/special/main.py", line 109, in execute\n    raise CommandNotFound\nlitecli.packages.special.main.CommandNotFound\n\nDuring handling of the above exception, another exception occurred:\n\nTraceback (most recent call last):\n  File "/opt/homebrew/Cellar/litecli/1.9.0_2/libexec/lib/python3.11/site-packages/litecli/main.py", line 447, in one_iteration\n    for title, cur, headers, status in res:\n  File "/opt/homebrew/Cellar/litecli/1.9.0_2/libexec/lib/python3.11/site-packages/litecli/sqlexecute.py", line 133, in run\n    cur.execute(sql)\nsqlite3.OperationalError: no such table: urls\n'
2023-08-01 12:29:34,802 (17540/MainThread) litecli.main ERROR - sql: 'delete table urls', error: OperationalError('near "table": syntax error')
2023-08-01 12:29:34,804 (17540/MainThread) litecli.main ERROR - traceback: 'Traceback (most recent call last):\n  File "/opt/homebrew/Cellar/litecli/1.9.0_2/libexec/lib/python3.11/site-packages/litecli/sqlexecute.py", line 129, in run\n    for result in special.execute(cur, sql):\n                  ^^^^^^^^^^^^^^^^^^^^^^^^^\n  File "/opt/homebrew/Cellar/litecli/1.9.0_2/libexec/lib/python3.11/site-packages/litecli/packages/special/main.py", line 109, in execute\n    raise CommandNotFound\nlitecli.packages.special.main.CommandNotFound\n\nDuring handling of the above exception, another exception occurred:\n\nTraceback (most recent call last):\n  File "/opt/homebrew/Cellar/litecli/1.9.0_2/libexec/lib/python3.11/site-packages/litecli/main.py", line 447, in one_iteration\n    for title, cur, headers, status in res:\n  File "/opt/homebrew/Cellar/litecli/1.9.0_2/libexec/lib/python3.11/site-packages/litecli/sqlexecute.py", line 133, in run\n    cur.execute(sql)\nsqlite3.OperationalError: near "table": syntax error\n'
2023-08-01 12:29:44,700 (17540/MainThread) litecli.main ERROR - sql: 'delete table urls', error: OperationalError('near "table": syntax error')
2023-08-01 12:29:44,701 (17540/MainThread) litecli.main ERROR - traceback: 'Traceback (most recent call last):\n  File "/opt/homebrew/Cellar/litecli/1.9.0_2/libexec/lib/python3.11/site-packages/litecli/sqlexecute.py", line 129, in run\n    for result in special.execute(cur, sql):\n                  ^^^^^^^^^^^^^^^^^^^^^^^^^\n  File "/opt/homebrew/Cellar/litecli/1.9.0_2/libexec/lib/python3.11/site-packages/litecli/packages/special/main.py", line 109, in execute\n    raise CommandNotFound\nlitecli.packages.special.main.CommandNotFound\n\nDuring handling of the above exception, another exception occurred:\n\nTraceback (most recent call last):\n  File "/opt/homebrew/Cellar/litecli/1.9.0_2/libexec/lib/python3.11/site-packages/litecli/main.py", line 447, in one_iteration\n    for title, cur, headers, status in res:\n  File "/opt/homebrew/Cellar/litecli/1.9.0_2/libexec/lib/python3.11/site-packages/litecli/sqlexecute.py", line 133, in run\n    cur.execute(sql)\nsqlite3.OperationalError: near "table": syntax error\n'
2023-08-01 12:31:31,628 (17992/MainThread) litecli.main ERROR - sql: '.tavbles', error: OperationalError('near ".": syntax error')
2023-08-01 12:31:31,632 (17992/MainThread) litecli.main ERROR - traceback: 'Traceback (most recent call last):\n  File "/opt/homebrew/Cellar/litecli/1.9.0_2/libexec/lib/python3.11/site-packages/litecli/sqlexecute.py", line 129, in run\n    for result in special.execute(cur, sql):\n                  ^^^^^^^^^^^^^^^^^^^^^^^^^\n  File "/opt/homebrew/Cellar/litecli/1.9.0_2/libexec/lib/python3.11/site-packages/litecli/packages/special/main.py", line 109, in execute\n    raise CommandNotFound\nlitecli.packages.special.main.CommandNotFound\n\nDuring handling of the above exception, another exception occurred:\n\nTraceback (most recent call last):\n  File "/opt/homebrew/Cellar/litecli/1.9.0_2/libexec/lib/python3.11/site-packages/litecli/main.py", line 447, in one_iteration\n    for title, cur, headers, status in res:\n  File "/opt/homebrew/Cellar/litecli/1.9.0_2/libexec/lib/python3.11/site-packages/litecli/sqlexecute.py", line 133, in run\n    cur.execute(sql)\nsqlite3.OperationalError: near ".": syntax error\n'
2023-08-01 12:36:04,610 (18285/MainThread) litecli.main ERROR - sql: '.ta', error: OperationalError('near ".": syntax error')
2023-08-01 12:36:04,613 (18285/MainThread) litecli.main ERROR - traceback: 'Traceback (most recent call last):\n  File "/opt/homebrew/Cellar/litecli/1.9.0_2/libexec/lib/python3.11/site-packages/litecli/sqlexecute.py", line 129, in run\n    for result in special.execute(cur, sql):\n                  ^^^^^^^^^^^^^^^^^^^^^^^^^\n  File "/opt/homebrew/Cellar/litecli/1.9.0_2/libexec/lib/python3.11/site-packages/litecli/packages/special/main.py", line 109, in execute\n    raise CommandNotFound\nlitecli.packages.special.main.CommandNotFound\n\nDuring handling of the above exception, another exception occurred:\n\nTraceback (most recent call last):\n  File "/opt/homebrew/Cellar/litecli/1.9.0_2/libexec/lib/python3.11/site-packages/litecli/main.py", line 447, in one_iteration\n    for title, cur, headers, status in res:\n  File "/opt/homebrew/Cellar/litecli/1.9.0_2/libexec/lib/python3.11/site-packages/litecli/sqlexecute.py", line 133, in run\n    cur.execute(sql)\nsqlite3.OperationalError: near ".": syntax error\n'
2025-09-10 14:34:46,491 (41638/completion_refresh) litecli.sqlcompleter ERROR - Failed to get relation names.
Traceback (most recent call last):
  File "/opt/homebrew/Cellar/litecli/1.16.0/libexec/lib/python3.13/site-packages/litecli/sqlcompleter.py", line 321, in extend_relations
    data = [self.escaped_names(d) for d in data]
                                           ^^^^
  File "/opt/homebrew/Cellar/litecli/1.16.0/libexec/lib/python3.13/site-packages/litecli/sqlexecute.py", line 168, in tables
    with closing(self.conn.cursor()) as cur:
                 ^^^^^^^^^^^^^^^^
AttributeError: 'NoneType' object has no attribute 'cursor'
2025-09-10 14:34:46,514 (41638/completion_refresh) litecli.sqlcompleter ERROR - Failed to get column names.
Traceback (most recent call last):
  File "/opt/homebrew/Cellar/litecli/1.16.0/libexec/lib/python3.13/site-packages/litecli/sqlcompleter.py", line 353, in extend_columns
    column_data = [self.escaped_names(d) for d in column_data]
                                                  ^^^^^^^^^^^
  File "/opt/homebrew/Cellar/litecli/1.16.0/libexec/lib/python3.13/site-packages/litecli/sqlexecute.py", line 176, in table_columns
    with closing(self.conn.cursor()) as cur:
                 ^^^^^^^^^^^^^^^^
AttributeError: 'NoneType' object has no attribute 'cursor'
2025-09-10 14:34:46,514 (41638/completion_refresh) litecli.sqlcompleter ERROR - Failed to get function names.
Traceback (most recent call last):
  File "/opt/homebrew/Cellar/litecli/1.16.0/libexec/lib/python3.13/site-packages/litecli/sqlcompleter.py", line 369, in extend_functions
    func_data = [self.escaped_names(d) for d in func_data]
                                                ^^^^^^^^^
  File "/opt/homebrew/Cellar/litecli/1.16.0/libexec/lib/python3.13/site-packages/litecli/sqlexecute.py", line 194, in functions
    with closing(self.conn.cursor()) as cur:
                 ^^^^^^^^^^^^^^^^
AttributeError: 'NoneType' object has no attribute 'cursor'
2025-09-10 14:35:06,411 (41638/MainThread) litecli.main ERROR - sql: 'database', error: OperationalError('Not connected to database.')
2025-09-10 14:35:06,413 (41638/MainThread) litecli.main ERROR - traceback: 'Traceback (most recent call last):\n  File "/opt/homebrew/Cellar/litecli/1.16.0/libexec/lib/python3.13/site-packages/litecli/main.py", line 505, in one_iteration\n    mutating = output_res(res, start)\n  File "/opt/homebrew/Cellar/litecli/1.16.0/libexec/lib/python3.13/site-packages/litecli/main.py", line 396, in output_res\n    for title, cur, headers, status in res:\n                                       ^^^\n  File "/opt/homebrew/Cellar/litecli/1.16.0/libexec/lib/python3.13/site-packages/litecli/sqlexecute.py", line 124, in run\n    raise OperationalError("Not connected to database.")\nsqlite3.OperationalError: Not connected to database.\n'
2025-09-10 14:35:19,796 (41638/MainThread) litecli.main ERROR - sql: 'database headfirst_db', error: OperationalError('Not connected to database.')
2025-09-10 14:35:19,797 (41638/MainThread) litecli.main ERROR - traceback: 'Traceback (most recent call last):\n  File "/opt/homebrew/Cellar/litecli/1.16.0/libexec/lib/python3.13/site-packages/litecli/main.py", line 505, in one_iteration\n    mutating = output_res(res, start)\n  File "/opt/homebrew/Cellar/litecli/1.16.0/libexec/lib/python3.13/site-packages/litecli/main.py", line 396, in output_res\n    for title, cur, headers, status in res:\n                                       ^^^\n  File "/opt/homebrew/Cellar/litecli/1.16.0/libexec/lib/python3.13/site-packages/litecli/sqlexecute.py", line 124, in run\n    raise OperationalError("Not connected to database.")\nsqlite3.OperationalError: Not connected to database.\n'
2025-09-10 14:35:30,086 (41638/MainThread) litecli.main ERROR - sql: 'system', error: OperationalError('Not connected to database.')
2025-09-10 14:35:30,087 (41638/MainThread) litecli.main ERROR - traceback: 'Traceback (most recent call last):\n  File "/opt/homebrew/Cellar/litecli/1.16.0/libexec/lib/python3.13/site-packages/litecli/main.py", line 505, in one_iteration\n    mutating = output_res(res, start)\n  File "/opt/homebrew/Cellar/litecli/1.16.0/libexec/lib/python3.13/site-packages/litecli/main.py", line 396, in output_res\n    for title, cur, headers, status in res:\n                                       ^^^\n  File "/opt/homebrew/Cellar/litecli/1.16.0/libexec/lib/python3.13/site-packages/litecli/sqlexecute.py", line 124, in run\n    raise OperationalError("Not connected to database.")\nsqlite3.OperationalError: Not connected to database.\n'
2025-09-10 14:35:48,891 (43136/completion_refresh) litecli.sqlcompleter ERROR - Failed to get function names.
Traceback (most recent call last):
  File "/opt/homebrew/Cellar/litecli/1.16.0/libexec/lib/python3.13/site-packages/litecli/sqlcompleter.py", line 369, in extend_functions
    func_data = [self.escaped_names(d) for d in func_data]
                                                ^^^^^^^^^
  File "/opt/homebrew/Cellar/litecli/1.16.0/libexec/lib/python3.13/site-packages/litecli/sqlexecute.py", line 196, in functions
    cur.execute(self.functions_query % self.dbname)
    ~~~~~~~~~~~^^^^^^^^^^^^^^^^^^^^^^^^^^^^^^^^^^^^
sqlite3.OperationalError: no such table: INFORMATION_SCHEMA.ROUTINES
2025-09-10 14:36:40,611 (43136/completion_refresh) litecli.sqlcompleter ERROR - Failed to get function names.
Traceback (most recent call last):
  File "/opt/homebrew/Cellar/litecli/1.16.0/libexec/lib/python3.13/site-packages/litecli/sqlcompleter.py", line 369, in extend_functions
    func_data = [self.escaped_names(d) for d in func_data]
                                                ^^^^^^^^^
  File "/opt/homebrew/Cellar/litecli/1.16.0/libexec/lib/python3.13/site-packages/litecli/sqlexecute.py", line 196, in functions
    cur.execute(self.functions_query % self.dbname)
    ~~~~~~~~~~~^^^^^^^^^^^^^^^^^^^^^^^^^^^^^^^^^^^^
sqlite3.OperationalError: no such table: INFORMATION_SCHEMA.ROUTINES
2025-09-10 14:36:44,687 (43136/MainThread) litecli.main ERROR - sql: 'table', error: OperationalError('near "table": syntax error')
2025-09-10 14:36:44,687 (43136/MainThread) litecli.main ERROR - traceback: 'Traceback (most recent call last):\n  File "/opt/homebrew/Cellar/litecli/1.16.0/libexec/lib/python3.13/site-packages/litecli/sqlexecute.py", line 131, in run\n    for result in special.execute(cur, sql):\n                  ~~~~~~~~~~~~~~~^^^^^^^^^^\n  File "/opt/homebrew/Cellar/litecli/1.16.0/libexec/lib/python3.13/site-packages/litecli/packages/special/main.py", line 125, in execute\n    raise CommandNotFound\nlitecli.packages.special.main.CommandNotFound\n\nDuring handling of the above exception, another exception occurred:\n\nTraceback (most recent call last):\n  File "/opt/homebrew/Cellar/litecli/1.16.0/libexec/lib/python3.13/site-packages/litecli/main.py", line 505, in one_iteration\n    mutating = output_res(res, start)\n  File "/opt/homebrew/Cellar/litecli/1.16.0/libexec/lib/python3.13/site-packages/litecli/main.py", line 396, in output_res\n    for title, cur, headers, status in res:\n                                       ^^^\n  File "/opt/homebrew/Cellar/litecli/1.16.0/libexec/lib/python3.13/site-packages/litecli/sqlexecute.py", line 138, in run\n    cur.execute(sql)\n    ~~~~~~~~~~~^^^^^\nsqlite3.OperationalError: near "table": syntax error\n'
2025-09-10 14:36:46,720 (43136/MainThread) litecli.main ERROR - sql: 'list', error: OperationalError('near "list": syntax error')
2025-09-10 14:36:46,721 (43136/MainThread) litecli.main ERROR - traceback: 'Traceback (most recent call last):\n  File "/opt/homebrew/Cellar/litecli/1.16.0/libexec/lib/python3.13/site-packages/litecli/sqlexecute.py", line 131, in run\n    for result in special.execute(cur, sql):\n                  ~~~~~~~~~~~~~~~^^^^^^^^^^\n  File "/opt/homebrew/Cellar/litecli/1.16.0/libexec/lib/python3.13/site-packages/litecli/packages/special/main.py", line 125, in execute\n    raise CommandNotFound\nlitecli.packages.special.main.CommandNotFound\n\nDuring handling of the above exception, another exception occurred:\n\nTraceback (most recent call last):\n  File "/opt/homebrew/Cellar/litecli/1.16.0/libexec/lib/python3.13/site-packages/litecli/main.py", line 505, in one_iteration\n    mutating = output_res(res, start)\n  File "/opt/homebrew/Cellar/litecli/1.16.0/libexec/lib/python3.13/site-packages/litecli/main.py", line 396, in output_res\n    for title, cur, headers, status in res:\n                                       ^^^\n  File "/opt/homebrew/Cellar/litecli/1.16.0/libexec/lib/python3.13/site-packages/litecli/sqlexecute.py", line 138, in run\n    cur.execute(sql)\n    ~~~~~~~~~~~^^^^^\nsqlite3.OperationalError: near "list": syntax error\n'
2025-09-10 14:36:50,593 (43136/MainThread) litecli.main ERROR - sql: 'tables', error: OperationalError('near "tables": syntax error')
2025-09-10 14:36:50,594 (43136/MainThread) litecli.main ERROR - traceback: 'Traceback (most recent call last):\n  File "/opt/homebrew/Cellar/litecli/1.16.0/libexec/lib/python3.13/site-packages/litecli/sqlexecute.py", line 131, in run\n    for result in special.execute(cur, sql):\n                  ~~~~~~~~~~~~~~~^^^^^^^^^^\n  File "/opt/homebrew/Cellar/litecli/1.16.0/libexec/lib/python3.13/site-packages/litecli/packages/special/main.py", line 125, in execute\n    raise CommandNotFound\nlitecli.packages.special.main.CommandNotFound\n\nDuring handling of the above exception, another exception occurred:\n\nTraceback (most recent call last):\n  File "/opt/homebrew/Cellar/litecli/1.16.0/libexec/lib/python3.13/site-packages/litecli/main.py", line 505, in one_iteration\n    mutating = output_res(res, start)\n  File "/opt/homebrew/Cellar/litecli/1.16.0/libexec/lib/python3.13/site-packages/litecli/main.py", line 396, in output_res\n    for title, cur, headers, status in res:\n                                       ^^^\n  File "/opt/homebrew/Cellar/litecli/1.16.0/libexec/lib/python3.13/site-packages/litecli/sqlexecute.py", line 138, in run\n    cur.execute(sql)\n    ~~~~~~~~~~~^^^^^\nsqlite3.OperationalError: near "tables": syntax error\n'
2025-09-10 14:37:29,241 (43136/MainThread) litecli.main ERROR - sql: 'table', error: OperationalError('near "table": syntax error')
2025-09-10 14:37:29,243 (43136/MainThread) litecli.main ERROR - traceback: 'Traceback (most recent call last):\n  File "/opt/homebrew/Cellar/litecli/1.16.0/libexec/lib/python3.13/site-packages/litecli/sqlexecute.py", line 131, in run\n    for result in special.execute(cur, sql):\n                  ~~~~~~~~~~~~~~~^^^^^^^^^^\n  File "/opt/homebrew/Cellar/litecli/1.16.0/libexec/lib/python3.13/site-packages/litecli/packages/special/main.py", line 125, in execute\n    raise CommandNotFound\nlitecli.packages.special.main.CommandNotFound\n\nDuring handling of the above exception, another exception occurred:\n\nTraceback (most recent call last):\n  File "/opt/homebrew/Cellar/litecli/1.16.0/libexec/lib/python3.13/site-packages/litecli/main.py", line 505, in one_iteration\n    mutating = output_res(res, start)\n  File "/opt/homebrew/Cellar/litecli/1.16.0/libexec/lib/python3.13/site-packages/litecli/main.py", line 396, in output_res\n    for title, cur, headers, status in res:\n                                       ^^^\n  File "/opt/homebrew/Cellar/litecli/1.16.0/libexec/lib/python3.13/site-packages/litecli/sqlexecute.py", line 138, in run\n    cur.execute(sql)\n    ~~~~~~~~~~~^^^^^\nsqlite3.OperationalError: near "table": syntax error\n'
2025-09-10 14:37:37,071 (43136/MainThread) litecli.main ERROR - sql: 'view', error: OperationalError('near "view": syntax error')
2025-09-10 14:37:37,073 (43136/MainThread) litecli.main ERROR - traceback: 'Traceback (most recent call last):\n  File "/opt/homebrew/Cellar/litecli/1.16.0/libexec/lib/python3.13/site-packages/litecli/sqlexecute.py", line 131, in run\n    for result in special.execute(cur, sql):\n                  ~~~~~~~~~~~~~~~^^^^^^^^^^\n  File "/opt/homebrew/Cellar/litecli/1.16.0/libexec/lib/python3.13/site-packages/litecli/packages/special/main.py", line 125, in execute\n    raise CommandNotFound\nlitecli.packages.special.main.CommandNotFound\n\nDuring handling of the above exception, another exception occurred:\n\nTraceback (most recent call last):\n  File "/opt/homebrew/Cellar/litecli/1.16.0/libexec/lib/python3.13/site-packages/litecli/main.py", line 505, in one_iteration\n    mutating = output_res(res, start)\n  File "/opt/homebrew/Cellar/litecli/1.16.0/libexec/lib/python3.13/site-packages/litecli/main.py", line 396, in output_res\n    for title, cur, headers, status in res:\n                                       ^^^\n  File "/opt/homebrew/Cellar/litecli/1.16.0/libexec/lib/python3.13/site-packages/litecli/sqlexecute.py", line 138, in run\n    cur.execute(sql)\n    ~~~~~~~~~~~^^^^^\nsqlite3.OperationalError: near "view": syntax error\n'
